Workbook
Name Den: Converter!$D$1

Sheet Assumptions
A1: Period of Construction of restaurant – 3 Months.
A3: Start of Construction | G3: 43922
A4: Construction period | G4: 3 Months
A5: Date of Operations | G5: =EOMONTH(G3,2)+1 -> 44013
A6: Revenue
A8: Particulars | B8: Weekdays | C8: Weekend | E8: Particulars | F8: Weekdays | G8: Weekend
A9: Lunch | E9: Dinner
A10: APC | B10: =SUBTOTAL(9,B11:B13) -> 1500 | C10: =SUBTOTAL(9,C11:C13) -> 1700 | E10: APC | F10: =SUBTOTAL(9,F11:F13) -> 1600 | G10: =SUBTOTAL(9,G11:G13) -> 1900
A11: Alcoholic Beverages | B11: 300 | C11: 500 | E11: Alcoholic Beverages | F11: 400 | G11: 650
A12: Non Alcoholic Beverages | B12: 200 | C12: 200 | E12: Non Alcoholic Beverages | F12: 200 | G12: 250
A13: Food | B13: 1000 | C13: 1000 | E13: Food | F13: 1000 | G13: 1000
A14: Y-O-Y Growth price rate | B14: 0.05 | C14: 0.05 | E14: Y-O-Y Price Growth rate | F14: 0.05 | G14: 0.05
A16: Occupancy | E16: Occupancy
A17: Number of Covers Available | B17: 100 | C17: 100 | E17: Number of Covers Available | F17: 100 | G17: 100
A18: Number of Rounds Available | B18: 2 | C18: 2 | E18: Number of Rounds Available | F18: 2 | G18: 2
A19: Number of Covers Occupied/ Round | B19: 10 | C19: 13 | E19: Number of Covers Occupied/ Round | F19: 13 | G19: 15
A20: MoM growth | B20: 0.02 | C20: 0.04 | E20: MoM growth | F20: 0.02 | G20: 0.04
A21: Maximum Occupancy/Round | B21: 60 | C21: 80 | E21: Maximum Occupancy/Round | F21: 70 | G21: 90
A24: Direct Expenses
A25: Alcoholic Beverage cost (% of revenue) | G25: 0.35
A26: Non Alcoholic Beverages (% of revenue) | G26: 0.4
A27: Food (% of revenue) | G27: 0.3
A29: Salary
A30: Members of Team | E30: Number of Employees | F30: Salary / M | G30: Salary / M
A31: Receptionist | E31: 2 | F31: 20000 | G31: 40000
A32: Restaurants Manager | E32: 2 | F32: 50000 | G32: 100000
A33: Waiters | E33: 10 | F33: 20000 | G33: 200000
A34: Head Chef | E34: 1 | F34: 100000 | G34: 100000
A35: Chefs | E35: 2 | F35: 75000 | G35: 150000
A36: Assistant Chef | E36: 6 | F36: 30000 | G36: 180000
A37: Valet Parking | E37: 3 | F37: 17000 | G37: 51000
A38: Cleaners | E38: 5 | F38: 17000 | G38: 85000
A39: Bartender | E39: 4 | F39: 20000 | G39: 80000
A40: Total | G40: =SUM(G31:G39) -> 986000
A41: Staff salary will increase Y-o-Y basis | G41: 0.08
A42: Indirect Expenses
A43: Members of Team | E43: Number of Employees | F43: Salary / M | G43: Salary / M
A44: HR Manager | E44: 1 | F44: 50000 | G44: 50000
A45: Assistant Manager | E45: 2 | F45: 35000 | G45: 70000
A46: Security | E46: 2 | F46: 20000 | G46: 40000
...

Sheet Converter
A1: Currency in INR | B1: Model In: | C1: Lakhs | D1: =VLOOKUP(C1,A3:B9,2,0) -> 100000
A3: Ones | B3: 1
A4: Tens | B4: 10
A5: Hundreds | B5: 100
A6: Thousands | B6: 1000
A7: Lakhs | B7: 100000
A8: Millions | B8: 1000000
A9: Crores | B9: 10000000

Sheet Monthly Revenue
A1: All Final Values In: | B1: =Converter!C1 -> Lakhs
E2: 1 | F2: 2 | G2: 3 | H2: 4 | I2: 5 | J2: 6 | K2: 7 | L2: 8 | M2: 9 | N2: 10 | O2: 11 | P2: 12 | Q2: 13 | R2: 14 | S2: 15 | T2: 16 | U2: 17 | V2: 18 | W2: 19 | X2: 20 | Y2: 21 | Z2: 22 | AA2: 23 | AB2: 24 | AC2: 25 | AD2: 26 | AE2: 27 | AF2: 28 | AG2: 29 | AH2: 30 | AI2: 31 | AJ2: 32 | AK2: 33 | AL2: 34 | AM2: 35 | AN2: 36
E3: =EOMONTH(Assumptions!G3,0) -> 43951 | F3: =EOMONTH(E3,1) -> 43982 | G3: =EOMONTH(E3,1+1) -> 44012 | H3: =EOMONTH(F3,1+1) -> 44043 | I3: =EOMONTH(G3,1+1) -> 44074 | J3: =EOMONTH(H3,1+1) -> 44104 | K3: =EOMONTH(I3,1+1) -> 44135 | L3: =EOMONTH(J3,1+1) -> 44165 | M3: =EOMONTH(K3,1+1) -> 44196 | N3: =EOMONTH(L3,1+1) -> 44227 | ... AN3: =EOMONTH(AL3,1+1) -> 45016
A4: Operating Days | E4: =IF(E3>Assumptions!$G$5,DAY('Monthly Revenue'!E3),0) -> 0 | F4: =IF(F3>Assumptions!$G$5,DAY('Monthly Revenue'!F3),0) -> 0 | G4: =IF(G3>Assumptions!$G$5,DAY('Monthly Revenue'!G3),0) -> 0 | H4: =IF(H3>Assumptions!$G$5,DAY('Monthly Revenue'!H3),0) -> 31 | I4: =IF(I3>Assumptions!$G$5,DAY('Monthly Revenue'!I3),0) -> 31 | J4: =IF(J3>Assumptions!$G$5,DAY('Monthly Revenue'!J3),0) -> 30 | K4: =IF(K3>Assumptions!$G$5,DAY('Monthly Revenue'!K3),0) -> 31 | L4: =IF(L3>Assumptions!$G$5,DAY('Monthly Revenue'!L3),0) -> 30 | ... AN4: =IF(AN3>Assumptions!$G$5,DAY('Monthly Revenue'!AN3),0) -> 31
A5: No. of Weekdays in a month | E5: =IF(E4>0,NETWORKDAYS(D3+1,E3),0) -> 0 | F5: =IF(F4>0,NETWORKDAYS(E3+1,F3),0) -> 0 | G5: =IF(G4>0,NETWORKDAYS(F3+1,G3),0) -> 0 | H5: =IF(H4>0,NETWORKDAYS(G3+1,H3),0) -> 23 | I5: =IF(I4>0,NETWORKDAYS(H3+1,I3),0) -> 21 | J5: =IF(J4>0,NETWORKDAYS(I3+1,J3),0) -> 22 | K5: =IF(K4>0,NETWORKDAYS(J3+1,K3),0) -> 22 | L5: =IF(L4>0,NETWORKDAYS(K3+1,L3),0) -> 21 | ... AN5: =IF(AN4>0,NETWORKDAYS(AM3+1,AN3),0) -> 23
A6: no. of Weekends in a month | E6: =E4-E5 -> 0 | F6: =F4-F5 -> 0 | G6: =G4-G5 -> 0 | H6: =H4-H5 -> 8 | I6: =I4-I5 -> 10 | J6: =J4-J5 -> 8 | K6: =K4-K5 -> 9 | L6: =L4-L5 -> 9 | ... AN6: =AN4-AN5 -> 8
A8: No of Guests (per day)
A9: Weekdays
A10: Lunch | E10: =IF(E$5>0,MIN(MAX(Assumptions!$B$19*Assumptions!$B$18,'Monthly Revenue'!D10*(1+Assumptions!$B$20)),Assumptions!$B$21),0) -> 0 | F10: =IF(F$5>0,MIN(MAX(Assumptions!$B$19*Assumptions!$B$18,'Monthly Revenue'!E10*(1+Assumptions!$B$20)),Assumptions!$B$21),0) -> 0 | G10: =IF(G$5>0,MIN(MAX(Assumptions!$B$19*Assumptions!$B$18,'Monthly Revenue'!F10*(1+Assumptions!$B$20)),Assumptions!$B$21),0) -> 0 | H10: =IF(H$5>0,MIN(MAX(Assumptions!$B$19*Assumptions!$B$18,'Monthly Revenue'!G10*(1+Assumptions!$B$20)),Assumptions!$B$21),0) -> 20 | I10: =IF(I$5>0,MIN(MAX(Assumptions!$B$19*Assumptions!$B$18,'Monthly Revenue'!H10*(1+Assumptions!$B$20)),Assumptions!$B$21),0) -> 20.4 | J10: =IF(J$5>0,MIN(MAX(Assumptions!$B$19*Assumptions!$B$18,'Monthly Revenue'!I10*(1+Assumptions!$B$20)),Assumptions!$B$21),0) -> 20.808 | K10: =IF(K$5>0,MIN(MAX(Assumptions!$B$19*Assumptions!$B$18,'Monthly Revenue'!J10*(1+Assumptions!$B$20)),Assumptions!$B$21),0) -> 21.22416 | L10: =IF(L$5>0,MIN(MAX(Assumptions!$B$19*Assumptions!$B$18,'Monthly Revenue'!K10*(1+Assumptions!$B$20)),Assumptions!$B$21),0) -> 21.648643 | ... AN10: =IF(AN$5>0,MIN(MAX(Assumptions!$B$19*Assumptions!$B$18,'Monthly Revenue'!AM10*(1+Assumptions!$B$20)),Assumptions!$B$21),0) -> 37.690812
A11: Dinner | E11: =IF(E$5>0,MIN(MAX(Assumptions!$F$19*Assumptions!$F$18,'Monthly Revenue'!D11*(1+Assumptions!$F$20)),Assumptions!$F$21),0) -> 0 | F11: =IF(F$5>0,MIN(MAX(Assumptions!$F$19*Assumptions!$F$18,'Monthly Revenue'!E11*(1+Assumptions!$F$20)),Assumptions!$F$21),0) -> 0 | G11: =IF(G$5>0,MIN(MAX(Assumptions!$F$19*Assumptions!$F$18,'Monthly Revenue'!F11*(1+Assumptions!$F$20)),Assumptions!$F$21),0) -> 0 | H11: =IF(H$5>0,MIN(MAX(Assumptions!$F$19*Assumptions!$F$18,'Monthly Revenue'!G11*(1+Assumptions!$F$20)),Assumptions!$F$21),0) -> 26 | I11: =IF(I$5>0,MIN(MAX(Assumptions!$F$19*Assumptions!$F$18,'Monthly Revenue'!H11*(1+Assumptions!$F$20)),Assumptions!$F$21),0) -> 26.52 | J11: =IF(J$5>0,MIN(MAX(Assumptions!$F$19*Assumptions!$F$18,'Monthly Revenue'!I11*(1+Assumptions!$F$20)),Assumptions!$F$21),0) -> 27.0504 | K11: =IF(K$5>0,MIN(MAX(Assumptions!$F$19*Assumptions!$F$18,'Monthly Revenue'!J11*(1+Assumptions!$F$20)),Assumptions!$F$21),0) -> 27.591408 | L11: =IF(L$5>0,MIN(MAX(Assumptions!$F$19*Assumptions!$F$18,'Monthly Revenue'!K11*(1+Assumptions!$F$20)),Assumptions!$F$21),0) -> 28.143236 | ... AN11: =IF(AN$5>0,MIN(MAX(Assumptions!$F$19*Assumptions!$F$18,'Monthly Revenue'!AM11*(1+Assumptions!$F$20)),Assumptions!$F$21),0) -> 48.998055
A12: Weekends
A13: Lunch | E13: =IF(E$5>0,MIN(MAX(Assumptions!$C$19*Assumptions!$C$18,'Monthly Revenue'!D13*(1+Assumptions!$C$20)),Assumptions!$C$21),0) -> 0 | F13: =IF(F$5>0,MIN(MAX(Assumptions!$C$19*Assumptions!$C$18,'Monthly Revenue'!E13*(1+Assumptions!$C$20)),Assumptions!$C$21),0) -> 0 | G13: =IF(G$5>0,MIN(MAX(Assumptions!$C$19*Assumptions!$C$18,'Monthly Revenue'!F13*(1+Assumptions!$C$20)),Assumptions!$C$21),0) -> 0 | H13: =IF(H$5>0,MIN(MAX(Assumptions!$C$19*Assumptions!$C$18,'Monthly Revenue'!G13*(1+Assumptions!$C$20)),Assumptions!$C$21),0) -> 26 | I13: =IF(I$5>0,MIN(MAX(Assumptions!$C$19*Assumptions!$C$18,'Monthly Revenue'!H13*(1+Assumptions!$C$20)),Assumptions!$C$21),0) -> 27.04 | J13: =IF(J$5>0,MIN(MAX(Assumptions!$C$19*Assumptions!$C$18,'Monthly Revenue'!I13*(1+Assumptions!$C$20)),Assumptions!$C$21),0) -> 28.1216 | K13: =IF(K$5>0,MIN(MAX(Assumptions!$C$19*Assumptions!$C$18,'Monthly Revenue'!J13*(1+Assumptions!$C$20)),Assumptions!$C$21),0) -> 29.246464 | L13: =IF(L$5>0,MIN(MAX(Assumptions!$C$19*Assumptions!$C$18,'Monthly Revenue'!K13*(1+Assumptions!$C$20)),Assumptions!$C$21),0) -> 30.416323 | ... AN13: =IF(AN$5>0,MIN(MAX(Assumptions!$C$19*Assumptions!$C$18,'Monthly Revenue'!AM13*(1+Assumptions!$C$20)),Assumptions!$C$21),0) -> 80
A14: Dinner | E14: =IF(E$5>0,MIN(MAX(Assumptions!$G$19*Assumptions!$G$18,'Monthly Revenue'!D14*(1+Assumptions!$G$20)),Assumptions!$G$21),0) -> 0 | F14: =IF(F$5>0,MIN(MAX(Assumptions!$G$19*Assumptions!$G$18,'Monthly Revenue'!E14*(1+Assumptions!$G$20)),Assumptions!$G$21),0) -> 0 | G14: =IF(G$5>0,MIN(MAX(Assumptions!$G$19*Assumptions!$G$18,'Monthly Revenue'!F14*(1+Assumptions!$G$20)),Assumptions!$G$21),0) -> 0 | H14: =IF(H$5>0,MIN(MAX(Assumptions!$G$19*Assumptions!$G$18,'Monthly Revenue'!G14*(1+Assumptions!$G$20)),Assumptions!$G$21),0) -> 30 | I14: =IF(I$5>0,MIN(MAX(Assumptions!$G$19*Assumptions!$G$18,'Monthly Revenue'!H14*(1+Assumptions!$G$20)),Assumptions!$G$21),0) -> 31.2 | J14: =IF(J$5>0,MIN(MAX(Assumptions!$G$19*Assumptions!$G$18,'Monthly Revenue'!I14*(1+Assumptions!$G$20)),Assumptions!$G$21),0) -> 32.448 | K14: =IF(K$5>0,MIN(MAX(Assumptions!$G$19*Assumptions!$G$18,'Monthly Revenue'!J14*(1+Assumptions!$G$20)),Assumptions!$G$21),0) -> 33.74592 | L14: =IF(L$5>0,MIN(MAX(Assumptions!$G$19*Assumptions!$G$18,'Monthly Revenue'!K14*(1+Assumptions!$G$20)),Assumptions!$G$21),0) -> 35.095757 | ... AN14: =IF(AN$5>0,MIN(MAX(Assumptions!$G$19*Assumptions!$G$18,'Monthly Revenue'!AM14*(1+Assumptions!$G$20)),Assumptions!$G$21),0) -> 90
A16: Average per Customer (APC)
A17: Weekdays
A18: Lunch
A19: Alcoholic Beverages | E19: =IF(MOD(E$2,12)=4,MAX(D19*(1+Assumptions!$B$14),Assumptions!$B11),'Monthly Revenue'!D19) -> 0 | F19: =IF(MOD(F$2,12)=4,MAX(E19*(1+Assumptions!$B$14),Assumptions!$B11),'Monthly Revenue'!E19) -> 0 | G19: =IF(MOD(G$2,12)=4,MAX(F19*(1+Assumptions!$B$14),Assumptions!$B11),'Monthly Revenue'!F19) -> 0 | H19: =IF(MOD(H$2,12)=4,MAX(G19*(1+Assumptions!$B$14),Assumptions!$B11),'Monthly Revenue'!G19) -> 300 | I19: =IF(MOD(I$2,12)=4,MAX(H19*(1+Assumptions!$B$14),Assumptions!$B11),'Monthly Revenue'!H19) -> 300 | J19: =IF(MOD(J$2,12)=4,MAX(I19*(1+Assumptions!$B$14),Assumptions!$B11),'Monthly Revenue'!I19) -> 300 | K19: =IF(MOD(K$2,12)=4,MAX(J19*(1+Assumptions!$B$14),Assumptions!$B11),'Monthly Revenue'!J19) -> 300 | L19: =IF(MOD(L$2,12)=4,MAX(K19*(1+Assumptions!$B$14),Assumptions!$B11),'Monthly Revenue'!K19) -> 300 | ... AN19: =IF(MOD(AN$2,12)=4,MAX(AM19*(1+Assumptions!$B$14),Assumptions!$B11),'Monthly Revenue'!AM19) -> 330.75
A20: Non Alcoholic Beverages | E20: =IF(MOD(E$2,12)=4,MAX(D20*(1+Assumptions!$B$14),Assumptions!$B12),'Monthly Revenue'!D20) -> 0 | F20: =IF(MOD(F$2,12)=4,MAX(E20*(1+Assumptions!$B$14),Assumptions!$B12),'Monthly Revenue'!E20) -> 0 | G20: =IF(MOD(G$2,12)=4,MAX(F20*(1+Assumptions!$B$14),Assumptions!$B12),'Monthly Revenue'!F20) -> 0 | H20: =IF(MOD(H$2,12)=4,MAX(G20*(1+Assumptions!$B$14),Assumptions!$B12),'Monthly Revenue'!G20) -> 200 | I20: =IF(MOD(I$2,12)=4,MAX(H20*(1+Assumptions!$B$14),Assumptions!$B12),'Monthly Revenue'!H20) -> 200 | J20: =IF(MOD(J$2,12)=4,MAX(I20*(1+Assumptions!$B$14),Assumptions!$B12),'Monthly Revenue'!I20) -> 200 | K20: =IF(MOD(K$2,12)=4,MAX(J20*(1+Assumptions!$B$14),Assumptions!$B12),'Monthly Revenue'!J20) -> 200 | L20: =IF(MOD(L$2,12)=4,MAX(K20*(1+Assumptions!$B$14),Assumptions!$B12),'Monthly Revenue'!K20) -> 200 | ... AN20: =IF(MOD(AN$2,12)=4,MAX(AM20*(1+Assumptions!$B$14),Assumptions!$B12),'Monthly Revenue'!AM20) -> 220.5
A21: Food | E21: =IF(MOD(E$2,12)=4,MAX(D21*(1+Assumptions!$B$14),Assumptions!$B13),'Monthly Revenue'!D21) -> 0 | F21: =IF(MOD(F$2,12)=4,MAX(E21*(1+Assumptions!$B$14),Assumptions!$B13),'Monthly Revenue'!E21) -> 0 | G21: =IF(MOD(G$2,12)=4,MAX(F21*(1+Assumptions!$B$14),Assumptions!$B13),'Monthly Revenue'!F21) -> 0 | H21: =IF(MOD(H$2,12)=4,MAX(G21*(1+Assumptions!$B$14),Assumptions!$B13),'Monthly Revenue'!G21) -> 1000 | I21: =IF(MOD(I$2,12)=4,MAX(H21*(1+Assumptions!$B$14),Assumptions!$B13),'Monthly Revenue'!H21) -> 1000 | J21: =IF(MOD(J$2,12)=4,MAX(I21*(1+Assumptions!$B$14),Assumptions!$B13),'Monthly Revenue'!I21) -> 1000 | K21: =IF(MOD(K$2,12)=4,MAX(J21*(1+Assumptions!$B$14),Assumptions!$B13),'Monthly Revenue'!J21) -> 1000 | L21: =IF(MOD(L$2,12)=4,MAX(K21*(1+Assumptions!$B$14),Assumptions!$B13),'Monthly Revenue'!K21) -> 1000 | ... AN21: =IF(MOD(AN$2,12)=4,MAX(AM21*(1+Assumptions!$B$14),Assumptions!$B13),'Monthly Revenue'!AM21) -> 1102.5
A22: TOTAL | E22: =SUM(E19:E21) -> 0 | F22: =SUM(F19:F21) -> 0 | G22: =SUM(G19:G21) -> 0 | H22: =SUM(H19:H21) -> 1500 | I22: =SUM(I19:I21) -> 1500 | J22: =SUM(J19:J21) -> 1500 | K22: =SUM(K19:K21) -> 1500 | L22: =SUM(L19:L21) -> 1500 | ... AN22: =SUM(AN19:AN21) -> 1653.75
A23: Dinner
A24: Alcoholic Beverages | E24: =IF(MOD(E$2,12)=4,MAX(D24*(1+Assumptions!$C$14),Assumptions!$F11),'Monthly Revenue'!D24) -> 0 | F24: =IF(MOD(F$2,12)=4,MAX(E24*(1+Assumptions!$C$14),Assumptions!$F11),'Monthly Revenue'!E24) -> 0 | G24: =IF(MOD(G$2,12)=4,MAX(F24*(1+Assumptions!$C$14),Assumptions!$F11),'Monthly Revenue'!F24) -> 0 | H24: =IF(MOD(H$2,12)=4,MAX(G24*(1+Assumptions!$C$14),Assumptions!$F11),'Monthly Revenue'!G24) -> 400 | I24: =IF(MOD(I$2,12)=4,MAX(H24*(1+Assumptions!$C$14),Assumptions!$F11),'Monthly Revenue'!H24) -> 400 | J24: =IF(MOD(J$2,12)=4,MAX(I24*(1+Assumptions!$C$14),Assumptions!$F11),'Monthly Revenue'!I24) -> 400 | K24: =IF(MOD(K$2,12)=4,MAX(J24*(1+Assumptions!$C$14),Assumptions!$F11),'Monthly Revenue'!J24) -> 400 | L24: =IF(MOD(L$2,12)=4,MAX(K24*(1+Assumptions!$C$14),Assumptions!$F11),'Monthly Revenue'!K24) -> 400 | ... AN24: =IF(MOD(AN$2,12)=4,MAX(AM24*(1+Assumptions!$C$14),Assumptions!$F11),'Monthly Revenue'!AM24) -> 441
A25: Non Alcoholic Beverages | E25: =IF(MOD(E$2,12)=4,MAX(D25*(1+Assumptions!$C$14),Assumptions!$F12),'Monthly Revenue'!D25) -> 0 | F25: =IF(MOD(F$2,12)=4,MAX(E25*(1+Assumptions!$C$14),Assumptions!$F12),'Monthly Revenue'!E25) -> 0 | G25: =IF(MOD(G$2,12)=4,MAX(F25*(1+Assumptions!$C$14),Assumptions!$F12),'Monthly Revenue'!F25) -> 0 | H25: =IF(MOD(H$2,12)=4,MAX(G25*(1+Assumptions!$C$14),Assumptions!$F12),'Monthly Revenue'!G25) -> 200 | I25: =IF(MOD(I$2,12)=4,MAX(H25*(1+Assumptions!$C$14),Assumptions!$F12),'Monthly Revenue'!H25) -> 200 | J25: =IF(MOD(J$2,12)=4,MAX(I25*(1+Assumptions!$C$14),Assumptions!$F12),'Monthly Revenue'!I25) -> 200 | K25: =IF(MOD(K$2,12)=4,MAX(J25*(1+Assumptions!$C$14),Assumptions!$F12),'Monthly Revenue'!J25) -> 200 | L25: =IF(MOD(L$2,12)=4,MAX(K25*(1+Assumptions!$C$14),Assumptions!$F12),'Monthly Revenue'!K25) -> 200 | ... AN25: =IF(MOD(AN$2,12)=4,MAX(AM25*(1+Assumptions!$C$14),Assumptions!$F12),'Monthly Revenue'!AM25) -> 220.5
A26: Food | E26: =IF(MOD(E$2,12)=4,MAX(D26*(1+Assumptions!$C$14),Assumptions!$F13),'Monthly Revenue'!D26) -> 0 | F26: =IF(MOD(F$2,12)=4,MAX(E26*(1+Assumptions!$C$14),Assumptions!$F13),'Monthly Revenue'!E26) -> 0 | G26: =IF(MOD(G$2,12)=4,MAX(F26*(1+Assumptions!$C$14),Assumptions!$F13),'Monthly Revenue'!F26) -> 0 | H26: =IF(MOD(H$2,12)=4,MAX(G26*(1+Assumptions!$C$14),Assumptions!$F13),'Monthly Revenue'!G26) -> 1000 | I26: =IF(MOD(I$2,12)=4,MAX(H26*(1+Assumptions!$C$14),Assumptions!$F13),'Monthly Revenue'!H26) -> 1000 | J26: =IF(MOD(J$2,12)=4,MAX(I26*(1+Assumptions!$C$14),Assumptions!$F13),'Monthly Revenue'!I26) -> 1000 | K26: =IF(MOD(K$2,12)=4,MAX(J26*(1+Assumptions!$C$14),Assumptions!$F13),'Monthly Revenue'!J26) -> 1000 | L26: =IF(MOD(L$2,12)=4,MAX(K26*(1+Assumptions!$C$14),Assumptions!$F13),'Monthly Revenue'!K26) -> 1000 | ... AN26: =IF(MOD(AN$2,12)=4,MAX(AM26*(1+Assumptions!$C$14),Assumptions!$F13),'Monthly Revenue'!AM26) -> 1102.5
A27: TOTAL | E27: =SUM(E24:E26) -> 0 | F27: =SUM(F24:F26) -> 0 | G27: =SUM(G24:G26) -> 0 | H27: =SUM(H24:H26) -> 1600 | I27: =SUM(I24:I26) -> 1600 | J27: =SUM(J24:J26) -> 1600 | K27: =SUM(K24:K26) -> 1600 | L27: =SUM(L24:L26) -> 1600 | ... AN27: =SUM(AN24:AN26) -> 1764
A28: Weekends
A29: Lunch
A30: Alcoholic Beverages | E30: =IF(MOD(E$2,12)=4,MAX(D30*(1+Assumptions!$C$14),Assumptions!$C11),'Monthly Revenue'!D30) -> 0 | F30: =IF(MOD(F$2,12)=4,MAX(E30*(1+Assumptions!$C$14),Assumptions!$C11),'Monthly Revenue'!E30) -> 0 | G30: =IF(MOD(G$2,12)=4,MAX(F30*(1+Assumptions!$C$14),Assumptions!$C11),'Monthly Revenue'!F30) -> 0 | H30: =IF(MOD(H$2,12)=4,MAX(G30*(1+Assumptions!$C$14),Assumptions!$C11),'Monthly Revenue'!G30) -> 500 | I30: =IF(MOD(I$2,12)=4,MAX(H30*(1+Assumptions!$C$14),Assumptions!$C11),'Monthly Revenue'!H30) -> 500 | J30: =IF(MOD(J$2,12)=4,MAX(I30*(1+Assumptions!$C$14),Assumptions!$C11),'Monthly Revenue'!I30) -> 500 | K30: =IF(MOD(K$2,12)=4,MAX(J30*(1+Assumptions!$C$14),Assumptions!$C11),'Monthly Revenue'!J30) -> 500 | L30: =IF(MOD(L$2,12)=4,MAX(K30*(1+Assumptions!$C$14),Assumptions!$C11),'Monthly Revenue'!K30) -> 500 | ... AN30: =IF(MOD(AN$2,12)=4,MAX(AM30*(1+Assumptions!$C$14),Assumptions!$C11),'Monthly Revenue'!AM30) -> 551.25
A31: Non Alcoholic Beverages | E31: =IF(MOD(E$2,12)=4,MAX(D31*(1+Assumptions!$C$14),Assumptions!$C12),'Monthly Revenue'!D31) -> 0 | F31: =IF(MOD(F$2,12)=4,MAX(E31*(1+Assumptions!$C$14),Assumptions!$C12),'Monthly Revenue'!E31) -> 0 | G31: =IF(MOD(G$2,12)=4,MAX(F31*(1+Assumptions!$C$14),Assumptions!$C12),'Monthly Revenue'!F31) -> 0 | H31: =IF(MOD(H$2,12)=4,MAX(G31*(1+Assumptions!$C$14),Assumptions!$C12),'Monthly Revenue'!G31) -> 200 | I31: =IF(MOD(I$2,12)=4,MAX(H31*(1+Assumptions!$C$14),Assumptions!$C12),'Monthly Revenue'!H31) -> 200 | J31: =IF(MOD(J$2,12)=4,MAX(I31*(1+Assumptions!$C$14),Assumptions!$C12),'Monthly Revenue'!I31) -> 200 | K31: =IF(MOD(K$2,12)=4,MAX(J31*(1+Assumptions!$C$14),Assumptions!$C12),'Monthly Revenue'!J31) -> 200 | L31: =IF(MOD(L$2,12)=4,MAX(K31*(1+Assumptions!$C$14),Assumptions!$C12),'Monthly Revenue'!K31) -> 200 | ... AN31: =IF(MOD(AN$2,12)=4,MAX(AM31*(1+Assumptions!$C$14),Assumptions!$C12),'Monthly Revenue'!AM31) -> 220.5
A32: Food | E32: =IF(MOD(E$2,12)=4,MAX(D32*(1+Assumptions!$C$14),Assumptions!$C13),'Monthly Revenue'!D32) -> 0 | F32: =IF(MOD(F$2,12)=4,MAX(E32*(1+Assumptions!$C$14),Assumptions!$C13),'Monthly Revenue'!E32) -> 0 | G32: =IF(MOD(G$2,12)=4,MAX(F32*(1+Assumptions!$C$14),Assumptions!$C13),'Monthly Revenue'!F32) -> 0 | H32: =IF(MOD(H$2,12)=4,MAX(G32*(1+Assumptions!$C$14),Assumptions!$C13),'Monthly Revenue'!G32) -> 1000 | I32: =IF(MOD(I$2,12)=4,MAX(H32*(1+Assumptions!$C$14),Assumptions!$C13),'Monthly Revenue'!H32) -> 1000 | J32: =IF(MOD(J$2,12)=4,MAX(I32*(1+Assumptions!$C$14),Assumptions!$C13),'Monthly Revenue'!I32) -> 1000 | K32: =IF(MOD(K$2,12)=4,MAX(J32*(1+Assumptions!$C$14),Assumptions!$C13),'Monthly Revenue'!J32) -> 1000 | L32: =IF(MOD(L$2,12)=4,MAX(K32*(1+Assumptions!$C$14),Assumptions!$C13),'Monthly Revenue'!K32) -> 1000 | ... AN32: =IF(MOD(AN$2,12)=4,MAX(AM32*(1+Assumptions!$C$14),Assumptions!$C13),'Monthly Revenue'!AM32) -> 1102.5
A33: TOTAL | E33: =SUM(E30:E32) -> 0 | F33: =SUM(F30:F32) -> 0 | G33: =SUM(G30:G32) -> 0 | H33: =SUM(H30:H32) -> 1700 | I33: =SUM(I30:I32) -> 1700 | J33: =SUM(J30:J32) -> 1700 | K33: =SUM(K30:K32) -> 1700 | L33: =SUM(L30:L32) -> 1700 | ... AN33: =SUM(AN30:AN32) -> 1874.25
A34: Dinner
A35: Alcoholic Beverages | E35: =IF(MOD(E$2,12)=4,MAX(D35*(1+Assumptions!$G$14),Assumptions!$G11),'Monthly Revenue'!D35) -> 0 | F35: =IF(MOD(F$2,12)=4,MAX(E35*(1+Assumptions!$G$14),Assumptions!$G11),'Monthly Revenue'!E35) -> 0 | G35: =IF(MOD(G$2,12)=4,MAX(F35*(1+Assumptions!$G$14),Assumptions!$G11),'Monthly Revenue'!F35) -> 0 | H35: =IF(MOD(H$2,12)=4,MAX(G35*(1+Assumptions!$G$14),Assumptions!$G11),'Monthly Revenue'!G35) -> 650 | I35: =IF(MOD(I$2,12)=4,MAX(H35*(1+Assumptions!$G$14),Assumptions!$G11),'Monthly Revenue'!H35) -> 650 | J35: =IF(MOD(J$2,12)=4,MAX(I35*(1+Assumptions!$G$14),Assumptions!$G11),'Monthly Revenue'!I35) -> 650 | K35: =IF(MOD(K$2,12)=4,MAX(J35*(1+Assumptions!$G$14),Assumptions!$G11),'Monthly Revenue'!J35) -> 650 | L35: =IF(MOD(L$2,12)=4,MAX(K35*(1+Assumptions!$G$14),Assumptions!$G11),'Monthly Revenue'!K35) -> 650 | ... AN35: =IF(MOD(AN$2,12)=4,MAX(AM35*(1+Assumptions!$G$14),Assumptions!$G11),'Monthly Revenue'!AM35) -> 716.625
A36: Non Alcoholic Beverages | E36: =IF(MOD(E$2,12)=4,MAX(D36*(1+Assumptions!$G$14),Assumptions!$G12),'Monthly Revenue'!D36) -> 0 | F36: =IF(MOD(F$2,12)=4,MAX(E36*(1+Assumptions!$G$14),Assumptions!$G12),'Monthly Revenue'!E36) -> 0 | G36: =IF(MOD(G$2,12)=4,MAX(F36*(1+Assumptions!$G$14),Assumptions!$G12),'Monthly Revenue'!F36) -> 0 | H36: =IF(MOD(H$2,12)=4,MAX(G36*(1+Assumptions!$G$14),Assumptions!$G12),'Monthly Revenue'!G36) -> 250 | I36: =IF(MOD(I$2,12)=4,MAX(H36*(1+Assumptions!$G$14),Assumptions!$G12),'Monthly Revenue'!H36) -> 250 | J36: =IF(MOD(J$2,12)=4,MAX(I36*(1+Assumptions!$G$14),Assumptions!$G12),'Monthly Revenue'!I36) -> 250 | K36: =IF(MOD(K$2,12)=4,MAX(J36*(1+Assumptions!$G$14),Assumptions!$G12),'Monthly Revenue'!J36) -> 250 | L36: =IF(MOD(L$2,12)=4,MAX(K36*(1+Assumptions!$G$14),Assumptions!$G12),'Monthly Revenue'!K36) -> 250 | ... AN36: =IF(MOD(AN$2,12)=4,MAX(AM36*(1+Assumptions!$G$14),Assumptions!$G12),'Monthly Revenue'!AM36) -> 275.625
A37: Food | E37: =IF(MOD(E$2,12)=4,MAX(D37*(1+Assumptions!$G$14),Assumptions!$G13),'Monthly Revenue'!D37) -> 0 | F37: =IF(MOD(F$2,12)=4,MAX(E37*(1+Assumptions!$G$14),Assumptions!$G13),'Monthly Revenue'!E37) -> 0 | G37: =IF(MOD(G$2,12)=4,MAX(F37*(1+Assumptions!$G$14),Assumptions!$G13),'Monthly Revenue'!F37) -> 0 | H37: =IF(MOD(H$2,12)=4,MAX(G37*(1+Assumptions!$G$14),Assumptions!$G13),'Monthly Revenue'!G37) -> 1000 | I37: =IF(MOD(I$2,12)=4,MAX(H37*(1+Assumptions!$G$14),Assumptions!$G13),'Monthly Revenue'!H37) -> 1000 | J37: =IF(MOD(J$2,12)=4,MAX(I37*(1+Assumptions!$G$14),Assumptions!$G13),'Monthly Revenue'!I37) -> 1000 | K37: =IF(MOD(K$2,12)=4,MAX(J37*(1+Assumptions!$G$14),Assumptions!$G13),'Monthly Revenue'!J37) -> 1000 | L37: =IF(MOD(L$2,12)=4,MAX(K37*(1+Assumptions!$G$14),Assumptions!$G13),'Monthly Revenue'!K37) -> 1000 | ... AN37: =IF(MOD(AN$2,12)=4,MAX(AM37*(1+Assumptions!$G$14),Assumptions!$G13),'Monthly Revenue'!AM37) -> 1102.5
A38: TOTAL | E38: =SUM(E35:E37) -> 0 | F38: =SUM(F35:F37) -> 0 | G38: =SUM(G35:G37) -> 0 | H38: =SUM(H35:H37) -> 1900 | I38: =SUM(I35:I37) -> 1900 | J38: =SUM(J35:J37) -> 1900 | K38: =SUM(K35:K37) -> 1900 | L38: =SUM(L35:L37) -> 1900 | ... AN38: =SUM(AN35:AN37) -> 2094.75
A40: Revenue per Month
A42: Weekdays
A44: Lunch
A45: Alcoholic Beverages | E45: =E19*E$10*E$5/Den -> 0 | F45: =F19*F$10*F$5/Den -> 0 | G45: =G19*G$10*G$5/Den -> 0 | H45: =H19*H$10*H$5/Den -> 1.38 | I45: =I19*I$10*I$5/Den -> 1.2852 | J45: =J19*J$10*J$5/Den -> 1.373328 | K45: =K19*K$10*K$5/Den -> 1.4007946 | L45: =L19*L$10*L$5/Den -> 1.3638645 | ... AN45: =AN19*AN$10*AN$5/Den -> 2.8672343
...

Sheet Monthly P&L
A1: All Final Values In: | B1: =Converter!C1 -> Lakhs
E2: 1 | F2: 2 | G2: 3 | H2: 4 | I2: 5 | J2: 6 | K2: 7 | L2: 8 | M2: 9 | N2: 10 | O2: 11 | P2: 12 | Q2: 13 | R2: 14 | S2: 15 | T2: 16 | U2: 17 | V2: 18 | W2: 19 | X2: 20 | Y2: 21 | Z2: 22 | AA2: 23 | AB2: 24 | AC2: 25 | AD2: 26 | AE2: 27 | AF2: 28 | AG2: 29 | AH2: 30 | AI2: 31 | AJ2: 32 | AK2: 33 | AL2: 34 | AM2: 35 | AN2: 36
E3: =EOMONTH(Assumptions!G3,0) -> 43951 | F3: =EOMONTH(E3,1) -> 43982 | G3: =EOMONTH(E3,1+1) -> 44012 | H3: =EOMONTH(F3,1+1) -> 44043 | I3: =EOMONTH(G3,1+1) -> 44074 | J3: =EOMONTH(H3,1+1) -> 44104 | K3: =EOMONTH(I3,1+1) -> 44135 | L3: =EOMONTH(J3,1+1) -> 44165 | M3: =EOMONTH(K3,1+1) -> 44196 | N3: =EOMONTH(L3,1+1) -> 44227 | ... AN3: =EOMONTH(AL3,1+1) -> 45016
A4: Revenue
A5: ='Monthly Revenue'!A71 -> Alcoholic Beverages | E5: ='Monthly Revenue'!E71 -> 0 | F5: ='Monthly Revenue'!F71 -> 0 | G5: ='Monthly Revenue'!G71 -> 0 | H5: ='Monthly Revenue'!H71 -> 6.372 | I5: ='Monthly Revenue'!I71 -> 6.89288 | J5: ='Monthly Revenue'!J71 -> 6.5659232 | K5: ='Monthly Revenue'!K71 -> 7.1190657 | L5: ='Monthly Revenue'!L71 -> 7.1497326 | ... AN5: ='Monthly Revenue'!AN71 -> 16.524807
A6: ='Monthly Revenue'!A72 -> Non Alcoholic Beverages | E6: ='Monthly Revenue'!E72 -> 0 | F6: ='Monthly Revenue'!F72 -> 0 | G6: ='Monthly Revenue'!G72 -> 0 | H6: ='Monthly Revenue'!H72 -> 3.132 | I6: ='Monthly Revenue'!I72 -> 3.29144 | J6: ='Monthly Revenue'!J72 -> 3.2046752 | K6: ='Monthly Revenue'!K72 -> 3.4336045 | L6: ='Monthly Revenue'!L72 -> 3.4284073 | ... AN6: ='Monthly Revenue'!AN72 -> 7.7921259
A7: ='Monthly Revenue'!A73 -> Food | E7: ='Monthly Revenue'!E73 -> 0 | F7: ='Monthly Revenue'!F73 -> 0 | G7: ='Monthly Revenue'!G73 -> 0 | H7: ='Monthly Revenue'!H73 -> 15.06 | I7: ='Monthly Revenue'!I73 -> 15.6772 | J7: ='Monthly Revenue'!J73 -> 15.374416 | K7: ='Monthly Revenue'!K73 -> 16.40874 | L7: ='Monthly Revenue'!L73 -> 16.352382 | ... AN7: ='Monthly Revenue'!AN73 -> 36.97613
A8: Total | E8: =SUM(E5:E7) -> 0 | F8: =SUM(F5:F7) -> 0 | G8: =SUM(G5:G7) -> 0 | H8: =SUM(H5:H7) -> 24.564 | I8: =SUM(I5:I7) -> 25.86152 | J8: =SUM(J5:J7) -> 25.145014 | K8: =SUM(K5:K7) -> 26.96141 | L8: =SUM(L5:L7) -> 26.930522 | ... AN8: =SUM(AN5:AN7) -> 61.293062
A10: Less Direct expenses
A11: =Assumptions!A25 -> Alcoholic Beverage cost (% of revenue) | E11: =E5*Assumptions!$G25 -> 0 | F11: =F5*Assumptions!$G25 -> 0 | G11: =G5*Assumptions!$G25 -> 0 | H11: =H5*Assumptions!$G25 -> 2.2302 | I11: =I5*Assumptions!$G25 -> 2.412508 | J11: =J5*Assumptions!$G25 -> 2.2980731 | K11: =K5*Assumptions!$G25 -> 2.491673 | L11: =L5*Assumptions!$G25 -> 2.5024064 | ... AN11: =AN5*Assumptions!$G25 -> 5.7836825
A12: =Assumptions!A26 -> Non Alcoholic Beverages (% of revenue) | E12: =E6*Assumptions!$G26 -> 0 | F12: =F6*Assumptions!$G26 -> 0 | G12: =G6*Assumptions!$G26 -> 0 | H12: =H6*Assumptions!$G26 -> 1.2528 | I12: =I6*Assumptions!$G26 -> 1.316576 | J12: =J6*Assumptions!$G26 -> 1.2818701 | K12: =K6*Assumptions!$G26 -> 1.3734418 | L12: =L6*Assumptions!$G26 -> 1.3713629 | ... AN12: =AN6*Assumptions!$G26 -> 3.1168504
A13: =Assumptions!A27 -> Food (% of revenue) | E13: =E7*Assumptions!$G27 -> 0 | F13: =F7*Assumptions!$G27 -> 0 | G13: =G7*Assumptions!$G27 -> 0 | H13: =H7*Assumptions!$G27 -> 4.518 | I13: =I7*Assumptions!$G27 -> 4.70316 | J13: =J7*Assumptions!$G27 -> 4.6123248 | K13: =K7*Assumptions!$G27 -> 4.9226219 | L13: =L7*Assumptions!$G27 -> 4.9057145 | ... AN13: =AN7*Assumptions!$G27 -> 11.092839
A14: Staff salary | E14: =IF(MOD(E$2,12)=4,MAX(D14*(1+Assumptions!$G$41),Assumptions!$G$40/Den),'Monthly P&L'!D14) -> 0 | F14: =IF(MOD(F$2,12)=4,MAX(E14*(1+Assumptions!$G$41),Assumptions!$G$40/Den),'Monthly P&L'!E14) -> 0 | G14: =IF(MOD(G$2,12)=4,MAX(F14*(1+Assumptions!$G$41),Assumptions!$G$40/Den),'Monthly P&L'!F14) -> 0 | H14: =IF(MOD(H$2,12)=4,MAX(G14*(1+Assumptions!$G$41),Assumptions!$G$40/Den),'Monthly P&L'!G14) -> 9.86 | I14: =IF(MOD(I$2,12)=4,MAX(H14*(1+Assumptions!$G$41),Assumptions!$G$40/Den),'Monthly P&L'!H14) -> 9.86 | J14: =IF(MOD(J$2,12)=4,MAX(I14*(1+Assumptions!$G$41),Assumptions!$G$40/Den),'Monthly P&L'!I14) -> 9.86 | K14: =IF(MOD(K$2,12)=4,MAX(J14*(1+Assumptions!$G$41),Assumptions!$G$40/Den),'Monthly P&L'!J14) -> 9.86 | L14: =IF(MOD(L$2,12)=4,MAX(K14*(1+Assumptions!$G$41),Assumptions!$G$40/Den),'Monthly P&L'!K14) -> 9.86 | ... AN14: =IF(MOD(AN$2,12)=4,MAX(AM14*(1+Assumptions!$G$41),Assumptions!$G$40/Den),'Monthly P&L'!AM14) -> 11.500704
A15: Total Direct expenses | E15: =SUM(E11:E14) -> 0 | F15: =SUM(F11:F14) -> 0 | G15: =SUM(G11:G14) -> 0 | H15: =SUM(H11:H14) -> 17.861 | I15: =SUM(I11:I14) -> 18.292244 | J15: =SUM(J11:J14) -> 18.052268 | K15: =SUM(K11:K14) -> 18.647737 | L15: =SUM(L11:L14) -> 18.639484 | ... AN15: =SUM(AN11:AN14) -> 31.494076
A17: Other Staff salary | E17: =IF(MOD(E$2,12)=4,MAX(D17*(1+Assumptions!$G$41),Assumptions!$G$50/Den),'Monthly P&L'!D17) -> 0 | F17: =IF(MOD(F$2,12)=4,MAX(E17*(1+Assumptions!$G$41),Assumptions!$G$50/Den),'Monthly P&L'!E17) -> 0 | G17: =IF(MOD(G$2,12)=4,MAX(F17*(1+Assumptions!$G$41),Assumptions!$G$50/Den),'Monthly P&L'!F17) -> 0 | H17: =IF(MOD(H$2,12)=4,MAX(G17*(1+Assumptions!$G$41),Assumptions!$G$50/Den),'Monthly P&L'!G17) -> 3.8 | I17: =IF(MOD(I$2,12)=4,MAX(H17*(1+Assumptions!$G$41),Assumptions!$G$50/Den),'Monthly P&L'!H17) -> 3.8 | J17: =IF(MOD(J$2,12)=4,MAX(I17*(1+Assumptions!$G$41),Assumptions!$G$50/Den),'Monthly P&L'!I17) -> 3.8 | K17: =IF(MOD(K$2,12)=4,MAX(J17*(1+Assumptions!$G$41),Assumptions!$G$50/Den),'Monthly P&L'!J17) -> 3.8 | L17: =IF(MOD(L$2,12)=4,MAX(K17*(1+Assumptions!$G$41),Assumptions!$G$50/Den),'Monthly P&L'!K17) -> 3.8 | ... AN17: =IF(MOD(AN$2,12)=4,MAX(AM17*(1+Assumptions!$G$41),Assumptions!$G$50/Den),'Monthly P&L'!AM17) -> 4.43232
A18: =Assumptions!A52 -> Rotalty to brand (% Of Revenue) | E18: =E8*Assumptions!$G$52 -> 0 | F18: =F8*Assumptions!$G$52 -> 0 | G18: =G8*Assumptions!$G$52 -> 0 | H18: =H8*Assumptions!$G$52 -> 1.2282 | I18: =I8*Assumptions!$G$52 -> 1.293076 | J18: =J8*Assumptions!$G$52 -> 1.2572507 | K18: =K8*Assumptions!$G$52 -> 1.3480705 | L18: =L8*Assumptions!$G$52 -> 1.3465261 | ... AN18: =AN8*Assumptions!$G$52 -> 3.0646531
A19: =Assumptions!A53 -> Rent (as per contract) (% of revenue) | E19: =E8*Assumptions!$G$53 -> 0 | F19: =F8*Assumptions!$G$53 -> 0 | G19: =G8*Assumptions!$G$53 -> 0 | H19: =H8*Assumptions!$G$53 -> 2.4564 | I19: =I8*Assumptions!$G$53 -> 2.586152 | J19: =J8*Assumptions!$G$53 -> 2.5145014 | K19: =K8*Assumptions!$G$53 -> 2.696141 | L19: =L8*Assumptions!$G$53 -> 2.6930522 | ... AN19: =AN8*Assumptions!$G$53 -> 6.1293062
A20: =Assumptions!A54 -> Water Cost (per month) | E20: =IF(MOD(E$2,12)=4,MAX(D20*(1+Assumptions!$G$41),Assumptions!$G54/Den),'Monthly P&L'!D20) -> 0 | F20: =IF(MOD(F$2,12)=4,MAX(E20*(1+Assumptions!$G$41),Assumptions!$G54/Den),'Monthly P&L'!E20) -> 0 | G20: =IF(MOD(G$2,12)=4,MAX(F20*(1+Assumptions!$G$41),Assumptions!$G54/Den),'Monthly P&L'!F20) -> 0 | H20: =IF(MOD(H$2,12)=4,MAX(G20*(1+Assumptions!$G$41),Assumptions!$G54/Den),'Monthly P&L'!G20) -> 0.1 | I20: =IF(MOD(I$2,12)=4,MAX(H20*(1+Assumptions!$G$41),Assumptions!$G54/Den),'Monthly P&L'!H20) -> 0.1 | J20: =IF(MOD(J$2,12)=4,MAX(I20*(1+Assumptions!$G$41),Assumptions!$G54/Den),'Monthly P&L'!I20) -> 0.1 | K20: =IF(MOD(K$2,12)=4,MAX(J20*(1+Assumptions!$G$41),Assumptions!$G54/Den),'Monthly P&L'!J20) -> 0.1 | L20: =IF(MOD(L$2,12)=4,MAX(K20*(1+Assumptions!$G$41),Assumptions!$G54/Den),'Monthly P&L'!K20) -> 0.1 | ... AN20: =IF(MOD(AN$2,12)=4,MAX(AM20*(1+Assumptions!$G$41),Assumptions!$G54/Den),'Monthly P&L'!AM20) -> 0.11664
A21: =Assumptions!A55 -> Maintenance (per month) | E21: =IF(MOD(E$2,12)=4,MAX(D21*(1+Assumptions!$G$41),Assumptions!$G55/Den),'Monthly P&L'!D21) -> 0 | F21: =IF(MOD(F$2,12)=4,MAX(E21*(1+Assumptions!$G$41),Assumptions!$G55/Den),'Monthly P&L'!E21) -> 0 | G21: =IF(MOD(G$2,12)=4,MAX(F21*(1+Assumptions!$G$41),Assumptions!$G55/Den),'Monthly P&L'!F21) -> 0 | H21: =IF(MOD(H$2,12)=4,MAX(G21*(1+Assumptions!$G$41),Assumptions!$G55/Den),'Monthly P&L'!G21) -> 0.5 | I21: =IF(MOD(I$2,12)=4,MAX(H21*(1+Assumptions!$G$41),Assumptions!$G55/Den),'Monthly P&L'!H21) -> 0.5 | J21: =IF(MOD(J$2,12)=4,MAX(I21*(1+Assumptions!$G$41),Assumptions!$G55/Den),'Monthly P&L'!I21) -> 0.5 | K21: =IF(MOD(K$2,12)=4,MAX(J21*(1+Assumptions!$G$41),Assumptions!$G55/Den),'Monthly P&L'!J21) -> 0.5 | L21: =IF(MOD(L$2,12)=4,MAX(K21*(1+Assumptions!$G$41),Assumptions!$G55/Den),'Monthly P&L'!K21) -> 0.5 | ... AN21: =IF(MOD(AN$2,12)=4,MAX(AM21*(1+Assumptions!$G$41),Assumptions!$G55/Den),'Monthly P&L'!AM21) -> 0.5832
A22: =Assumptions!A56 -> Marketing cost (per month) | E22: =IF(MOD(E$2,12)=4,MAX(D22*(1+Assumptions!$G$41),Assumptions!$G56/Den),'Monthly P&L'!D22) -> 0 | F22: =IF(MOD(F$2,12)=4,MAX(E22*(1+Assumptions!$G$41),Assumptions!$G56/Den),'Monthly P&L'!E22) -> 0 | G22: =IF(MOD(G$2,12)=4,MAX(F22*(1+Assumptions!$G$41),Assumptions!$G56/Den),'Monthly P&L'!F22) -> 0 | H22: =IF(MOD(H$2,12)=4,MAX(G22*(1+Assumptions!$G$41),Assumptions!$G56/Den),'Monthly P&L'!G22) -> 0.25 | I22: =IF(MOD(I$2,12)=4,MAX(H22*(1+Assumptions!$G$41),Assumptions!$G56/Den),'Monthly P&L'!H22) -> 0.25 | J22: =IF(MOD(J$2,12)=4,MAX(I22*(1+Assumptions!$G$41),Assumptions!$G56/Den),'Monthly P&L'!I22) -> 0.25 | K22: =IF(MOD(K$2,12)=4,MAX(J22*(1+Assumptions!$G$41),Assumptions!$G56/Den),'Monthly P&L'!J22) -> 0.25 | L22: =IF(MOD(L$2,12)=4,MAX(K22*(1+Assumptions!$G$41),Assumptions!$G56/Den),'Monthly P&L'!K22) -> 0.25 | ... AN22: =IF(MOD(AN$2,12)=4,MAX(AM22*(1+Assumptions!$G$41),Assumptions!$G56/Den),'Monthly P&L'!AM22) -> 0.2916
A23: =Assumptions!A57 -> Electricity (Based on area Rs./sq. Ft.) | E23: =IF(MOD(E$2,12)=4,MAX(D23*(1+Assumptions!$G$41),Assumptions!$G57*Assumptions!$G$67/Den),'Monthly P&L'!D23) -> 0 | F23: =IF(MOD(F$2,12)=4,MAX(E23*(1+Assumptions!$G$41),Assumptions!$G57*Assumptions!$G$67/Den),'Monthly P&L'!E23) -> 0 | G23: =IF(MOD(G$2,12)=4,MAX(F23*(1+Assumptions!$G$41),Assumptions!$G57*Assumptions!$G$67/Den),'Monthly P&L'!F23) -> 0 | H23: =IF(MOD(H$2,12)=4,MAX(G23*(1+Assumptions!$G$41),Assumptions!$G57*Assumptions!$G$67/Den),'Monthly P&L'!G23) -> 0.266 | I23: =IF(MOD(I$2,12)=4,MAX(H23*(1+Assumptions!$G$41),Assumptions!$G57*Assumptions!$G$67/Den),'Monthly P&L'!H23) -> 0.266 | J23: =IF(MOD(J$2,12)=4,MAX(I23*(1+Assumptions!$G$41),Assumptions!$G57*Assumptions!$G$67/Den),'Monthly P&L'!I23) -> 0.266 | K23: =IF(MOD(K$2,12)=4,MAX(J23*(1+Assumptions!$G$41),Assumptions!$G57*Assumptions!$G$67/Den),'Monthly P&L'!J23) -> 0.266 | L23: =IF(MOD(L$2,12)=4,MAX(K23*(1+Assumptions!$G$41),Assumptions!$G57*Assumptions!$G$67/Den),'Monthly P&L'!K23) -> 0.266 | ... AN23: =IF(MOD(AN$2,12)=4,MAX(AM23*(1+Assumptions!$G$41),Assumptions!$G57*Assumptions!$G$67/Den),'Monthly P&L'!AM23) -> 0.3102624
A24: =Assumptions!A58 -> Phone and internet (per month) | E24: =IF(MOD(E$2,12)=4,MAX(D24*(1+Assumptions!$G$41),Assumptions!$G58/Den),'Monthly P&L'!D24) -> 0 | F24: =IF(MOD(F$2,12)=4,MAX(E24*(1+Assumptions!$G$41),Assumptions!$G58/Den),'Monthly P&L'!E24) -> 0 | G24: =IF(MOD(G$2,12)=4,MAX(F24*(1+Assumptions!$G$41),Assumptions!$G58/Den),'Monthly P&L'!F24) -> 0 | H24: =IF(MOD(H$2,12)=4,MAX(G24*(1+Assumptions!$G$41),Assumptions!$G58/Den),'Monthly P&L'!G24) -> 0.15 | I24: =IF(MOD(I$2,12)=4,MAX(H24*(1+Assumptions!$G$41),Assumptions!$G58/Den),'Monthly P&L'!H24) -> 0.15 | J24: =IF(MOD(J$2,12)=4,MAX(I24*(1+Assumptions!$G$41),Assumptions!$G58/Den),'Monthly P&L'!I24) -> 0.15 | K24: =IF(MOD(K$2,12)=4,MAX(J24*(1+Assumptions!$G$41),Assumptions!$G58/Den),'Monthly P&L'!J24) -> 0.15 | L24: =IF(MOD(L$2,12)=4,MAX(K24*(1+Assumptions!$G$41),Assumptions!$G58/Den),'Monthly P&L'!K24) -> 0.15 | ... AN24: =IF(MOD(AN$2,12)=4,MAX(AM24*(1+Assumptions!$G$41),Assumptions!$G58/Den),'Monthly P&L'!AM24) -> 0.17496
A25: =Assumptions!A59 -> Housekeeping & Consumables (% of revenue) | E25: =E8*Assumptions!$G$59 -> 0 | F25: =F8*Assumptions!$G$59 -> 0 | G25: =G8*Assumptions!$G$59 -> 0 | H25: =H8*Assumptions!$G$59 -> 0.49128 | I25: =I8*Assumptions!$G$59 -> 0.5172304 | J25: =J8*Assumptions!$G$59 -> 0.50290029 | K25: =K8*Assumptions!$G$59 -> 0.53922819 | L25: =L8*Assumptions!$G$59 -> 0.53861043 | ... AN25: =AN8*Assumptions!$G$59 -> 1.2258612
A26: =Assumptions!A60 -> Payment Settlement Charges (% or revenue) | E26: =E8*Assumptions!$G$61*Assumptions!$G$60 -> 0 | F26: =F8*Assumptions!$G$61*Assumptions!$G$60 -> 0 | G26: =G8*Assumptions!$G$61*Assumptions!$G$60 -> 0 | H26: =H8*Assumptions!$G$61*Assumptions!$G$60 -> 0.18423 | I26: =I8*Assumptions!$G$61*Assumptions!$G$60 -> 0.1939614 | J26: =J8*Assumptions!$G$61*Assumptions!$G$60 -> 0.18858761 | K26: =K8*Assumptions!$G$61*Assumptions!$G$60 -> 0.20221057 | L26: =L8*Assumptions!$G$61*Assumptions!$G$60 -> 0.20197891 | ... AN26: =AN8*Assumptions!$G$61*Assumptions!$G$60 -> 0.45969797
A27: Total Indirect expenses | E27: =SUM(E17:E26) -> 0 | F27: =SUM(F17:F26) -> 0 | G27: =SUM(G17:G26) -> 0 | H27: =SUM(H17:H26) -> 9.42611 | I27: =SUM(I17:I26) -> 9.6564198 | J27: =SUM(J17:J26) -> 9.5292401 | K27: =SUM(K17:K26) -> 9.8516502 | L27: =SUM(L17:L26) -> 9.8461676 | ... AN27: =SUM(AN17:AN26) -> 16.788501
A29: EBITDA | E29: =E8-E15-E27 -> 0 | F29: =F8-F15-F27 -> 0 | G29: =G8-G15-G27 -> 0 | H29: =H8-H15-H27 -> -2.72311 | I29: =I8-I15-I27 -> -2.0871438 | J29: =J8-J15-J27 -> -2.4364937 | K29: =K8-K15-K27 -> -1.5379772 | L29: =L8-L15-L27 -> -1.5551298 | ... AN29: =AN8-AN15-AN27 -> 13.010486
A31: EBITDA margin % | E31: =E29/E8 -> #DIV/0! | F31: =F29/F8 -> #DIV/0! | G31: =G29/G8 -> #DIV/0! | H31: =H29/H8 -> -0.11085776 | I31: =I29/I8 -> -0.080704607 | J31: =J29/J8 -> -0.096897684 | K31: =K29/K8 -> -0.057043648 | L31: =L29/L8 -> -0.057745994 | ... AN31: =AN29/AN8 -> 0.21226686
A33: End of sheet

Sheet Capital Structure
A1: All Final Values In: | B1: =Converter!C1 -> Lakhs
E2: 0
E3: =Assumptions!G3 -> 43922
A4: Fixed Assets
A5: =Assumptions!A79 -> Kitchen Equipments and cutlery | E5: =Assumptions!$G$79*Assumptions!$G$70/Den -> 30
A6: =Assumptions!A80 -> Refrigeration Equipments | E6: =Assumptions!$G$80*Assumptions!$G$70/Den -> 50
A7: =Assumptions!A81 -> Furniture & Fixtures | E7: =Assumptions!$G$81*Assumptions!$G$69/Den -> 51
A8: =Assumptions!A82 -> Restaurants Décor | E8: =Assumptions!$G$82*Assumptions!$G$69/Den -> 60
A9: Total | E9: =SUM(E5:E8) -> 191
A10: Add: Rent deposit | E10: =Assumptions!$G$83/Den -> 10
A11: Add: Working capital | E11: =Assumptions!$G$87/Den -> 24
A13: Total Funds required | E13: =E9+E10+E11 -> 225
A15: Sources of Funds
A16: Equity | B16: =Assumptions!G100 -> 1 | E16: =E13*B16 -> 225
A17: Debt | B17: =1-B16 -> 0 | E17: =E13*B17 -> 0
A19: Total Funds Contributed | E19: =E16+E17 -> 225
A22: End of sheet

Sheet Fixed Asset Schedule
A1: All Final Values In: | B1: =Converter!C1 -> Lakhs
E2: 1 | F2: 2 | G2: 3
E3: =EOMONTH(Assumptions!G3,11) -> 44286 | F3: =EOMONTH(E3,12) -> 44651 | G3: =EOMONTH(F3,12) -> 45016
A4: ='Capital Structure'!A5 -> Kitchen Equipments and cutlery
A5: Opening balance | E5: 0 | F5: =E9 -> 26.634247 | G5: =F9 -> 22.63911
A6: Add: Purchases | E6: ='Capital Structure'!E5 -> 30 | F6: 0 | G6: 0
A7: Less: Sales | E7: 0 | F7: 0 | G7: 0
A8: Less: Depreciation | E8: =(E5+E6-E7)*Assumptions!$G$96*MIN(365,'Fixed Asset Schedule'!E$3-Assumptions!$G$5)/365 -> 3.3657534 | F8: =(F5+F6-F7)*Assumptions!$G$96*MIN(365,'Fixed Asset Schedule'!F$3-Assumptions!$G$5)/365 -> 3.995137 | G8: =(G5+G6-G7)*Assumptions!$G$96*MIN(365,'Fixed Asset Schedule'!G$3-Assumptions!$G$5)/365 -> 3.3958664
A9: Closing Balance | E9: =E5+E6-E7-E8 -> 26.634247 | F9: =F5+F6-F7-F8 -> 22.63911 | G9: =G5+G6-G7-G8 -> 19.243243
A12: ='Capital Structure'!A6 -> Refrigeration Equipments
A13: Opening balance | E13: 0 | F13: =E17 -> 44.390411 | G13: =F17 -> 37.731849
A14: Add: Purchases | E14: ='Capital Structure'!E6 -> 50 | F14: 0 | G14: 0
A15: Less: Sales | E15: 0 | F15: 0 | G15: 0
A16: Less: Depreciation | E16: =(E13+E14-E15)*Assumptions!$G$96*MIN(365,'Fixed Asset Schedule'!E$3-Assumptions!$G$5)/365 -> 5.609589 | F16: =(F13+F14-F15)*Assumptions!$G$96*MIN(365,'Fixed Asset Schedule'!F$3-Assumptions!$G$5)/365 -> 6.6585616 | G16: =(G13+G14-G15)*Assumptions!$G$96*MIN(365,'Fixed Asset Schedule'!G$3-Assumptions!$G$5)/365 -> 5.6597774
A17: Closing Balance | E17: =E13+E14-E15-E16 -> 44.390411 | F17: =F13+F14-F15-F16 -> 37.731849 | G17: =G13+G14-G15-G16 -> 32.072072
A19: ='Capital Structure'!A7 -> Furniture & Fixtures
A20: Opening balance | E20: 0 | F20: =E24 -> 47.185479 | G20: =F24 -> 42.466932
A21: Add: Purchases | E21: ='Capital Structure'!E7 -> 51 | F21: 0 | G21: 0
A22: Less: Sales | E22: 0 | F22: 0 | G22: 0
A23: Less: Depreciation | E23: =(E20+E21-E22)*Assumptions!$G$97*MIN(365,'Fixed Asset Schedule'!E$3-Assumptions!$G$5)/365 -> 3.8145205 | F23: =(F20+F21-F22)*Assumptions!$G$97*MIN(365,'Fixed Asset Schedule'!F$3-Assumptions!$G$5)/365 -> 4.7185479 | G23: =(G20+G21-G22)*Assumptions!$G$97*MIN(365,'Fixed Asset Schedule'!G$3-Assumptions!$G$5)/365 -> 4.2466932
A24: Closing Balance | E24: =E20+E21-E22-E23 -> 47.185479 | F24: =F20+F21-F22-F23 -> 42.466932 | G24: =G20+G21-G22-G23 -> 38.220238
A26: ='Capital Structure'!A8 -> Restaurants Décor
A27: Opening balance | E27: 0 | F27: =E31 -> 55.512329 | G27: =F31 -> 49.961096
A28: Add: Purchases | E28: ='Capital Structure'!E8 -> 60 | F28: 0 | G28: 0
A29: Less: Sales | E29: 0 | F29: 0 | G29: 0
A30: Less: Depreciation | E30: =(E27+E28-E29)*Assumptions!$G$97*MIN(365,'Fixed Asset Schedule'!E$3-Assumptions!$G$5)/365 -> 4.4876712 | F30: =(F27+F28-F29)*Assumptions!$G$97*MIN(365,'Fixed Asset Schedule'!F$3-Assumptions!$G$5)/365 -> 5.5512329 | G30: =(G27+G28-G29)*Assumptions!$G$97*MIN(365,'Fixed Asset Schedule'!G$3-Assumptions!$G$5)/365 -> 4.9961096
A31: Closing Balance | E31: =E27+E28-E29-E30 -> 55.512329 | F31: =F27+F28-F29-F30 -> 49.961096 | G31: =G27+G28-G29-G30 -> 44.964986
A33: End of sheet

Sheet Working Capital
A1: All Final Values In: | B1: =Converter!C1 -> Lakhs
E2: 1 | F2: 2 | G2: 3
E3: =EOMONTH(Assumptions!G3,11) -> 44286 | F3: =EOMONTH(E3,12) -> 44651 | G3: =EOMONTH(F3,12) -> 45016
A4: Current Assets
A5: Inventory
A6: ='Monthly Revenue'!A71 -> Alcoholic Beverages | E6: =SUMIF('Monthly P&L'!$E$3:$AN$3,'Working Capital'!E$3,'Monthly P&L'!$E11:$AN11)/31*Assumptions!$G89 -> 2.7021509 | F6: =SUMIF('Monthly P&L'!$E$3:$AN$3,'Working Capital'!F$3,'Monthly P&L'!$E11:$AN11)/31*Assumptions!$G89 -> 4.0194709 | G6: =SUMIF('Monthly P&L'!$E$3:$AN$3,'Working Capital'!G$3,'Monthly P&L'!$E11:$AN11)/31*Assumptions!$G89 -> 5.5971121
A7: ='Monthly Revenue'!A72 -> Non Alcoholic Beverages | E7: =SUMIF('Monthly P&L'!$E$3:$AN$3,'Working Capital'!E$3,'Monthly P&L'!$E12:$AN12)/31*Assumptions!$G90 -> 0.74897369 | F7: =SUMIF('Monthly P&L'!$E$3:$AN$3,'Working Capital'!F$3,'Monthly P&L'!$E12:$AN12)/31*Assumptions!$G90 -> 1.0914132 | G7: =SUMIF('Monthly P&L'!$E$3:$AN$3,'Working Capital'!G$3,'Monthly P&L'!$E12:$AN12)/31*Assumptions!$G90 -> 1.5081534
A8: ='Monthly Revenue'!A73 -> Food | E8: =SUMIF('Monthly P&L'!$E$3:$AN$3,'Working Capital'!E$3,'Monthly P&L'!$E13:$AN13)/31*Assumptions!$G91 -> 0.89648446 | F8: =SUMIF('Monthly P&L'!$E$3:$AN$3,'Working Capital'!F$3,'Monthly P&L'!$E13:$AN13)/31*Assumptions!$G91 -> 1.2974726 | G8: =SUMIF('Monthly P&L'!$E$3:$AN$3,'Working Capital'!G$3,'Monthly P&L'!$E13:$AN13)/31*Assumptions!$G91 -> 1.7891676
A9: Total | E9: =SUM(E6:E8) -> 4.347609 | F9: =SUM(F6:F8) -> 6.4083567 | G9: =SUM(G6:G8) -> 8.894433
A10: Current Liabilities
A11: Creditor for Expenses | E11: =SUMIF('Monthly P&L'!$E$3:$AN$3,'Working Capital'!E$3,'Monthly P&L'!$E27:$AN27)/31*Assumptions!$G92 -> 10.120191 | F11: =SUMIF('Monthly P&L'!$E$3:$AN$3,'Working Capital'!F$3,'Monthly P&L'!$E27:$AN27)/31*Assumptions!$G92 -> 12.90789 | G11: =SUMIF('Monthly P&L'!$E$3:$AN$3,'Working Capital'!G$3,'Monthly P&L'!$E27:$AN27)/31*Assumptions!$G92 -> 16.246936
A12: Creditor for Raw material
A13: ='Monthly Revenue'!A71 -> Alcoholic Beverages | E13: =SUMIF('Monthly P&L'!$E$3:$AN$3,'Working Capital'!E$3,'Monthly P&L'!$E11:$AN11)/31*Assumptions!$G$92 -> 2.7021509 | F13: =SUMIF('Monthly P&L'!$E$3:$AN$3,'Working Capital'!F$3,'Monthly P&L'!$E11:$AN11)/31*Assumptions!$G$92 -> 4.0194709 | G13: =SUMIF('Monthly P&L'!$E$3:$AN$3,'Working Capital'!G$3,'Monthly P&L'!$E11:$AN11)/31*Assumptions!$G$92 -> 5.5971121
A14: ='Monthly Revenue'!A72 -> Non Alcoholic Beverages | E14: =SUMIF('Monthly P&L'!$E$3:$AN$3,'Working Capital'!E$3,'Monthly P&L'!$E12:$AN12)/31*Assumptions!$G$92 -> 1.4979474 | F14: =SUMIF('Monthly P&L'!$E$3:$AN$3,'Working Capital'!F$3,'Monthly P&L'!$E12:$AN12)/31*Assumptions!$G$92 -> 2.1828264 | G14: =SUMIF('Monthly P&L'!$E$3:$AN$3,'Working Capital'!G$3,'Monthly P&L'!$E12:$AN12)/31*Assumptions!$G$92 -> 3.0163068
A15: ='Monthly Revenue'!A73 -> Food | E15: =SUMIF('Monthly P&L'!$E$3:$AN$3,'Working Capital'!E$3,'Monthly P&L'!$E13:$AN13)/31*Assumptions!$G$92 -> 5.3789068 | F15: =SUMIF('Monthly P&L'!$E$3:$AN$3,'Working Capital'!F$3,'Monthly P&L'!$E13:$AN13)/31*Assumptions!$G$92 -> 7.7848354 | G15: =SUMIF('Monthly P&L'!$E$3:$AN$3,'Working Capital'!G$3,'Monthly P&L'!$E13:$AN13)/31*Assumptions!$G$92 -> 10.735005
A16: Total | E16: =SUM(E11:E15) -> 19.699196 | F16: =SUM(F11:F15) -> 26.895023 | G16: =SUM(G11:G15) -> 35.595361
A18: Working Capital | E18: =E9-E16 -> -15.351587 | F18: =F9-F16 -> -20.486666 | G18: =G9-G16 -> -26.700928
A19: Changes in Working Capital | E19: =D18-E18 -> 15.351587 | F19: =E18-F18 -> 5.1350787 | G19: =F18-G18 -> 6.2142618

Sheet Annual P&L
A1: All Final Values In: | B1: =Converter!C1 -> Lakhs
E2: 1 | F2: 2 | G2: 3
D3: =Assumptions!G5 -> 44013 | E3: =EOMONTH(Assumptions!G3,11) -> 44286 | F3: =EOMONTH(E3,12) -> 44651 | G3: =EOMONTH(F3,12) -> 45016
A4: Revenue
A5: ='Monthly Revenue'!A71 -> Alcoholic Beverages | E5: =SUMIFS('Monthly P&L'!$E5:$AN5,'Monthly P&L'!$E$3:$AN$3,">"&'Annual P&L'!D$3,'Monthly P&L'!$E$3:$AN$3,"<="&'Annual P&L'!E$3) -> 64.585172 | F5: =SUMIFS('Monthly P&L'!$E5:$AN5,'Monthly P&L'!$E$3:$AN$3,">"&'Annual P&L'!E$3,'Monthly P&L'!$E$3:$AN$3,"<="&'Annual P&L'!F$3) -> 121.87672 | G5: =SUMIFS('Monthly P&L'!$E5:$AN5,'Monthly P&L'!$E$3:$AN$3,">"&'Annual P&L'!F$3,'Monthly P&L'!$E$3:$AN$3,"<="&'Annual P&L'!G$3) -> 180.72179
A6: ='Monthly Revenue'!A72 -> Non Alcoholic Beverages | E6: =SUMIFS('Monthly P&L'!$E6:$AN6,'Monthly P&L'!$E$3:$AN$3,">"&'Annual P&L'!D$3,'Monthly P&L'!$E$3:$AN$3,"<="&'Annual P&L'!E$3) -> 31.165448 | F6: =SUMIFS('Monthly P&L'!$E6:$AN6,'Monthly P&L'!$E$3:$AN$3,">"&'Annual P&L'!E$3,'Monthly P&L'!$E$3:$AN$3,"<="&'Annual P&L'!F$3) -> 57.732685 | G6: =SUMIFS('Monthly P&L'!$E6:$AN6,'Monthly P&L'!$E$3:$AN$3,">"&'Annual P&L'!F$3,'Monthly P&L'!$E$3:$AN$3,"<="&'Annual P&L'!G$3) -> 84.085991
A7: ='Monthly Revenue'!A73 -> Food | E7: =SUMIFS('Monthly P&L'!$E7:$AN7,'Monthly P&L'!$E$3:$AN$3,">"&'Annual P&L'!D$3,'Monthly P&L'!$E$3:$AN$3,"<="&'Annual P&L'!E$3) -> 148.95966 | F7: =SUMIFS('Monthly P&L'!$E7:$AN7,'Monthly P&L'!$E$3:$AN$3,">"&'Annual P&L'!E$3,'Monthly P&L'!$E$3:$AN$3,"<="&'Annual P&L'!F$3) -> 274.24132 | G7: =SUMIFS('Monthly P&L'!$E7:$AN7,'Monthly P&L'!$E$3:$AN$3,">"&'Annual P&L'!F$3,'Monthly P&L'!$E$3:$AN$3,"<="&'Annual P&L'!G$3) -> 397.0635
A8: Total | E8: =SUMIFS('Monthly P&L'!$E8:$AN8,'Monthly P&L'!$E$3:$AN$3,">"&'Annual P&L'!D$3,'Monthly P&L'!$E$3:$AN$3,"<="&'Annual P&L'!E$3) -> 244.71028 | F8: =SUMIFS('Monthly P&L'!$E8:$AN8,'Monthly P&L'!$E$3:$AN$3,">"&'Annual P&L'!E$3,'Monthly P&L'!$E$3:$AN$3,"<="&'Annual P&L'!F$3) -> 453.85072 | G8: =SUMIFS('Monthly P&L'!$E8:$AN8,'Monthly P&L'!$E$3:$AN$3,">"&'Annual P&L'!F$3,'Monthly P&L'!$E$3:$AN$3,"<="&'Annual P&L'!G$3) -> 661.87128
E9: =SUMIFS('Monthly P&L'!$E9:$AN9,'Monthly P&L'!$E$3:$AN$3,">"&'Annual P&L'!D$3,'Monthly P&L'!$E$3:$AN$3,"<="&'Annual P&L'!E$3) -> 0 | F9: =SUMIFS('Monthly P&L'!$E9:$AN9,'Monthly P&L'!$E$3:$AN$3,">"&'Annual P&L'!E$3,'Monthly P&L'!$E$3:$AN$3,"<="&'Annual P&L'!F$3) -> 0 | G9: =SUMIFS('Monthly P&L'!$E9:$AN9,'Monthly P&L'!$E$3:$AN$3,">"&'Annual P&L'!F$3,'Monthly P&L'!$E$3:$AN$3,"<="&'Annual P&L'!G$3) -> 0
A10: Less Direct expenses | E10: =SUMIFS('Monthly P&L'!$E10:$AN10,'Monthly P&L'!$E$3:$AN$3,">"&'Annual P&L'!D$3,'Monthly P&L'!$E$3:$AN$3,"<="&'Annual P&L'!E$3) -> 0 | F10: =SUMIFS('Monthly P&L'!$E10:$AN10,'Monthly P&L'!$E$3:$AN$3,">"&'Annual P&L'!E$3,'Monthly P&L'!$E$3:$AN$3,"<="&'Annual P&L'!F$3) -> 0 | G10: =SUMIFS('Monthly P&L'!$E10:$AN10,'Monthly P&L'!$E$3:$AN$3,">"&'Annual P&L'!F$3,'Monthly P&L'!$E$3:$AN$3,"<="&'Annual P&L'!G$3) -> 0
A11: =Assumptions!A25 -> Alcoholic Beverage cost (% of revenue) | E11: =SUMIFS('Monthly P&L'!$E11:$AN11,'Monthly P&L'!$E$3:$AN$3,">"&'Annual P&L'!D$3,'Monthly P&L'!$E$3:$AN$3,"<="&'Annual P&L'!E$3) -> 22.60481 | F11: =SUMIFS('Monthly P&L'!$E11:$AN11,'Monthly P&L'!$E$3:$AN$3,">"&'Annual P&L'!E$3,'Monthly P&L'!$E$3:$AN$3,"<="&'Annual P&L'!F$3) -> 42.656851 | G11: =SUMIFS('Monthly P&L'!$E11:$AN11,'Monthly P&L'!$E$3:$AN$3,">"&'Annual P&L'!F$3,'Monthly P&L'!$E$3:$AN$3,"<="&'Annual P&L'!G$3) -> 63.252626
A12: =Assumptions!A26 -> Non Alcoholic Beverages (% of revenue) | E12: =SUMIFS('Monthly P&L'!$E12:$AN12,'Monthly P&L'!$E$3:$AN$3,">"&'Annual P&L'!D$3,'Monthly P&L'!$E$3:$AN$3,"<="&'Annual P&L'!E$3) -> 12.466179 | F12: =SUMIFS('Monthly P&L'!$E12:$AN12,'Monthly P&L'!$E$3:$AN$3,">"&'Annual P&L'!E$3,'Monthly P&L'!$E$3:$AN$3,"<="&'Annual P&L'!F$3) -> 23.093074 | G12: =SUMIFS('Monthly P&L'!$E12:$AN12,'Monthly P&L'!$E$3:$AN$3,">"&'Annual P&L'!F$3,'Monthly P&L'!$E$3:$AN$3,"<="&'Annual P&L'!G$3) -> 33.634396
A13: =Assumptions!A27 -> Food (% of revenue) | E13: =SUMIFS('Monthly P&L'!$E13:$AN13,'Monthly P&L'!$E$3:$AN$3,">"&'Annual P&L'!D$3,'Monthly P&L'!$E$3:$AN$3,"<="&'Annual P&L'!E$3) -> 44.687898 | F13: =SUMIFS('Monthly P&L'!$E13:$AN13,'Monthly P&L'!$E$3:$AN$3,">"&'Annual P&L'!E$3,'Monthly P&L'!$E$3:$AN$3,"<="&'Annual P&L'!F$3) -> 82.272396 | G13: =SUMIFS('Monthly P&L'!$E13:$AN13,'Monthly P&L'!$E$3:$AN$3,">"&'Annual P&L'!F$3,'Monthly P&L'!$E$3:$AN$3,"<="&'Annual P&L'!G$3) -> 119.11905
A14: Staff salary | E14: =SUMIFS('Monthly P&L'!$E14:$AN14,'Monthly P&L'!$E$3:$AN$3,">"&'Annual P&L'!D$3,'Monthly P&L'!$E$3:$AN$3,"<="&'Annual P&L'!E$3) -> 88.74 | F14: =SUMIFS('Monthly P&L'!$E14:$AN14,'Monthly P&L'!$E$3:$AN$3,">"&'Annual P&L'!E$3,'Monthly P&L'!$E$3:$AN$3,"<="&'Annual P&L'!F$3) -> 125.4192 | G14: =SUMIFS('Monthly P&L'!$E14:$AN14,'Monthly P&L'!$E$3:$AN$3,">"&'Annual P&L'!F$3,'Monthly P&L'!$E$3:$AN$3,"<="&'Annual P&L'!G$3) -> 135.45274
A15: Total Direct expenses | E15: =SUMIFS('Monthly P&L'!$E15:$AN15,'Monthly P&L'!$E$3:$AN$3,">"&'Annual P&L'!D$3,'Monthly P&L'!$E$3:$AN$3,"<="&'Annual P&L'!E$3) -> 168.49889 | F15: =SUMIFS('Monthly P&L'!$E15:$AN15,'Monthly P&L'!$E$3:$AN$3,">"&'Annual P&L'!E$3,'Monthly P&L'!$E$3:$AN$3,"<="&'Annual P&L'!F$3) -> 273.44152 | G15: =SUMIFS('Monthly P&L'!$E15:$AN15,'Monthly P&L'!$E$3:$AN$3,">"&'Annual P&L'!F$3,'Monthly P&L'!$E$3:$AN$3,"<="&'Annual P&L'!G$3) -> 351.45881
E16: =SUMIFS('Monthly P&L'!$E16:$AN16,'Monthly P&L'!$E$3:$AN$3,">"&'Annual P&L'!D$3,'Monthly P&L'!$E$3:$AN$3,"<="&'Annual P&L'!E$3) -> 0 | F16: =SUMIFS('Monthly P&L'!$E16:$AN16,'Monthly P&L'!$E$3:$AN$3,">"&'Annual P&L'!E$3,'Monthly P&L'!$E$3:$AN$3,"<="&'Annual P&L'!F$3) -> 0 | G16: =SUMIFS('Monthly P&L'!$E16:$AN16,'Monthly P&L'!$E$3:$AN$3,">"&'Annual P&L'!F$3,'Monthly P&L'!$E$3:$AN$3,"<="&'Annual P&L'!G$3) -> 0
A17: Other Staff salary | E17: =SUMIFS('Monthly P&L'!$E17:$AN17,'Monthly P&L'!$E$3:$AN$3,">"&'Annual P&L'!D$3,'Monthly P&L'!$E$3:$AN$3,"<="&'Annual P&L'!E$3) -> 34.2 | F17: =SUMIFS('Monthly P&L'!$E17:$AN17,'Monthly P&L'!$E$3:$AN$3,">"&'Annual P&L'!E$3,'Monthly P&L'!$E$3:$AN$3,"<="&'Annual P&L'!F$3) -> 48.336 | G17: =SUMIFS('Monthly P&L'!$E17:$AN17,'Monthly P&L'!$E$3:$AN$3,">"&'Annual P&L'!F$3,'Monthly P&L'!$E$3:$AN$3,"<="&'Annual P&L'!G$3) -> 52.20288
A18: =Assumptions!A52 -> Rotalty to brand (% Of Revenue) | E18: =SUMIFS('Monthly P&L'!$E18:$AN18,'Monthly P&L'!$E$3:$AN$3,">"&'Annual P&L'!D$3,'Monthly P&L'!$E$3:$AN$3,"<="&'Annual P&L'!E$3) -> 12.235514 | F18: =SUMIFS('Monthly P&L'!$E18:$AN18,'Monthly P&L'!$E$3:$AN$3,">"&'Annual P&L'!E$3,'Monthly P&L'!$E$3:$AN$3,"<="&'Annual P&L'!F$3) -> 22.692536 | G18: =SUMIFS('Monthly P&L'!$E18:$AN18,'Monthly P&L'!$E$3:$AN$3,">"&'Annual P&L'!F$3,'Monthly P&L'!$E$3:$AN$3,"<="&'Annual P&L'!G$3) -> 33.093564
A19: =Assumptions!A53 -> Rent (as per contract) (% of revenue) | E19: =SUMIFS('Monthly P&L'!$E19:$AN19,'Monthly P&L'!$E$3:$AN$3,">"&'Annual P&L'!D$3,'Monthly P&L'!$E$3:$AN$3,"<="&'Annual P&L'!E$3) -> 24.471028 | F19: =SUMIFS('Monthly P&L'!$E19:$AN19,'Monthly P&L'!$E$3:$AN$3,">"&'Annual P&L'!E$3,'Monthly P&L'!$E$3:$AN$3,"<="&'Annual P&L'!F$3) -> 45.385072 | G19: =SUMIFS('Monthly P&L'!$E19:$AN19,'Monthly P&L'!$E$3:$AN$3,">"&'Annual P&L'!F$3,'Monthly P&L'!$E$3:$AN$3,"<="&'Annual P&L'!G$3) -> 66.187128
A20: =Assumptions!A54 -> Water Cost (per month) | E20: =SUMIFS('Monthly P&L'!$E20:$AN20,'Monthly P&L'!$E$3:$AN$3,">"&'Annual P&L'!D$3,'Monthly P&L'!$E$3:$AN$3,"<="&'Annual P&L'!E$3) -> 0.9 | F20: =SUMIFS('Monthly P&L'!$E20:$AN20,'Monthly P&L'!$E$3:$AN$3,">"&'Annual P&L'!E$3,'Monthly P&L'!$E$3:$AN$3,"<="&'Annual P&L'!F$3) -> 1.272 | G20: =SUMIFS('Monthly P&L'!$E20:$AN20,'Monthly P&L'!$E$3:$AN$3,">"&'Annual P&L'!F$3,'Monthly P&L'!$E$3:$AN$3,"<="&'Annual P&L'!G$3) -> 1.37376
A21: =Assumptions!A55 -> Maintenance (per month) | E21: =SUMIFS('Monthly P&L'!$E21:$AN21,'Monthly P&L'!$E$3:$AN$3,">"&'Annual P&L'!D$3,'Monthly P&L'!$E$3:$AN$3,"<="&'Annual P&L'!E$3) -> 4.5 | F21: =SUMIFS('Monthly P&L'!$E21:$AN21,'Monthly P&L'!$E$3:$AN$3,">"&'Annual P&L'!E$3,'Monthly P&L'!$E$3:$AN$3,"<="&'Annual P&L'!F$3) -> 6.36 | G21: =SUMIFS('Monthly P&L'!$E21:$AN21,'Monthly P&L'!$E$3:$AN$3,">"&'Annual P&L'!F$3,'Monthly P&L'!$E$3:$AN$3,"<="&'Annual P&L'!G$3) -> 6.8688
A22: =Assumptions!A56 -> Marketing cost (per month) | E22: =SUMIFS('Monthly P&L'!$E22:$AN22,'Monthly P&L'!$E$3:$AN$3,">"&'Annual P&L'!D$3,'Monthly P&L'!$E$3:$AN$3,"<="&'Annual P&L'!E$3) -> 2.25 | F22: =SUMIFS('Monthly P&L'!$E22:$AN22,'Monthly P&L'!$E$3:$AN$3,">"&'Annual P&L'!E$3,'Monthly P&L'!$E$3:$AN$3,"<="&'Annual P&L'!F$3) -> 3.18 | G22: =SUMIFS('Monthly P&L'!$E22:$AN22,'Monthly P&L'!$E$3:$AN$3,">"&'Annual P&L'!F$3,'Monthly P&L'!$E$3:$AN$3,"<="&'Annual P&L'!G$3) -> 3.4344
A23: =Assumptions!A57 -> Electricity (Based on area Rs./sq. Ft.) | E23: =SUMIFS('Monthly P&L'!$E23:$AN23,'Monthly P&L'!$E$3:$AN$3,">"&'Annual P&L'!D$3,'Monthly P&L'!$E$3:$AN$3,"<="&'Annual P&L'!E$3) -> 2.394 | F23: =SUMIFS('Monthly P&L'!$E23:$AN23,'Monthly P&L'!$E$3:$AN$3,">"&'Annual P&L'!E$3,'Monthly P&L'!$E$3:$AN$3,"<="&'Annual P&L'!F$3) -> 3.38352 | G23: =SUMIFS('Monthly P&L'!$E23:$AN23,'Monthly P&L'!$E$3:$AN$3,">"&'Annual P&L'!F$3,'Monthly P&L'!$E$3:$AN$3,"<="&'Annual P&L'!G$3) -> 3.6542016
A24: =Assumptions!A58 -> Phone and internet (per month) | E24: =SUMIFS('Monthly P&L'!$E24:$AN24,'Monthly P&L'!$E$3:$AN$3,">"&'Annual P&L'!D$3,'Monthly P&L'!$E$3:$AN$3,"<="&'Annual P&L'!E$3) -> 1.35 | F24: =SUMIFS('Monthly P&L'!$E24:$AN24,'Monthly P&L'!$E$3:$AN$3,">"&'Annual P&L'!E$3,'Monthly P&L'!$E$3:$AN$3,"<="&'Annual P&L'!F$3) -> 1.908 | G24: =SUMIFS('Monthly P&L'!$E24:$AN24,'Monthly P&L'!$E$3:$AN$3,">"&'Annual P&L'!F$3,'Monthly P&L'!$E$3:$AN$3,"<="&'Annual P&L'!G$3) -> 2.06064
A25: =Assumptions!A59 -> Housekeeping & Consumables (% of revenue) | E25: =SUMIFS('Monthly P&L'!$E25:$AN25,'Monthly P&L'!$E$3:$AN$3,">"&'Annual P&L'!D$3,'Monthly P&L'!$E$3:$AN$3,"<="&'Annual P&L'!E$3) -> 4.8942056 | F25: =SUMIFS('Monthly P&L'!$E25:$AN25,'Monthly P&L'!$E$3:$AN$3,">"&'Annual P&L'!E$3,'Monthly P&L'!$E$3:$AN$3,"<="&'Annual P&L'!F$3) -> 9.0770144 | G25: =SUMIFS('Monthly P&L'!$E25:$AN25,'Monthly P&L'!$E$3:$AN$3,">"&'Annual P&L'!F$3,'Monthly P&L'!$E$3:$AN$3,"<="&'Annual P&L'!G$3) -> 13.237426
A26: =Assumptions!A60 -> Payment Settlement Charges (% or revenue) | E26: =SUMIFS('Monthly P&L'!$E26:$AN26,'Monthly P&L'!$E$3:$AN$3,">"&'Annual P&L'!D$3,'Monthly P&L'!$E$3:$AN$3,"<="&'Annual P&L'!E$3) -> 1.8353271 | F26: =SUMIFS('Monthly P&L'!$E26:$AN26,'Monthly P&L'!$E$3:$AN$3,">"&'Annual P&L'!E$3,'Monthly P&L'!$E$3:$AN$3,"<="&'Annual P&L'!F$3) -> 3.4038804 | G26: =SUMIFS('Monthly P&L'!$E26:$AN26,'Monthly P&L'!$E$3:$AN$3,">"&'Annual P&L'!F$3,'Monthly P&L'!$E$3:$AN$3,"<="&'Annual P&L'!G$3) -> 4.9640346
A27: Total Indirect expenses | E27: =SUMIFS('Monthly P&L'!$E27:$AN27,'Monthly P&L'!$E$3:$AN$3,">"&'Annual P&L'!D$3,'Monthly P&L'!$E$3:$AN$3,"<="&'Annual P&L'!E$3) -> 89.030075 | F27: =SUMIFS('Monthly P&L'!$E27:$AN27,'Monthly P&L'!$E$3:$AN$3,">"&'Annual P&L'!E$3,'Monthly P&L'!$E$3:$AN$3,"<="&'Annual P&L'!F$3) -> 144.99802 | G27: =SUMIFS('Monthly P&L'!$E27:$AN27,'Monthly P&L'!$E$3:$AN$3,">"&'Annual P&L'!F$3,'Monthly P&L'!$E$3:$AN$3,"<="&'Annual P&L'!G$3) -> 187.07683
E28: =SUMIFS('Monthly P&L'!$E28:$AN28,'Monthly P&L'!$E$3:$AN$3,">"&'Annual P&L'!D$3,'Monthly P&L'!$E$3:$AN$3,"<="&'Annual P&L'!E$3) -> 0 | F28: =SUMIFS('Monthly P&L'!$E28:$AN28,'Monthly P&L'!$E$3:$AN$3,">"&'Annual P&L'!E$3,'Monthly P&L'!$E$3:$AN$3,"<="&'Annual P&L'!F$3) -> 0 | G28: =SUMIFS('Monthly P&L'!$E28:$AN28,'Monthly P&L'!$E$3:$AN$3,">"&'Annual P&L'!F$3,'Monthly P&L'!$E$3:$AN$3,"<="&'Annual P&L'!G$3) -> 0
A29: EBITDA | E29: =SUMIFS('Monthly P&L'!$E29:$AN29,'Monthly P&L'!$E$3:$AN$3,">"&'Annual P&L'!D$3,'Monthly P&L'!$E$3:$AN$3,"<="&'Annual P&L'!E$3) -> -12.818682 | F29: =SUMIFS('Monthly P&L'!$E29:$AN29,'Monthly P&L'!$E$3:$AN$3,">"&'Annual P&L'!E$3,'Monthly P&L'!$E$3:$AN$3,"<="&'Annual P&L'!F$3) -> 35.411178 | G29: =SUMIFS('Monthly P&L'!$E29:$AN29,'Monthly P&L'!$E$3:$AN$3,">"&'Annual P&L'!F$3,'Monthly P&L'!$E$3:$AN$3,"<="&'Annual P&L'!G$3) -> 123.33564
A30: less depreciation | E30: =SUM('Fixed Asset Schedule'!E8,'Fixed Asset Schedule'!E16,'Fixed Asset Schedule'!E23,'Fixed Asset Schedule'!E30) -> 17.277534 | F30: =SUM('Fixed Asset Schedule'!F8,'Fixed Asset Schedule'!F16,'Fixed Asset Schedule'!F23,'Fixed Asset Schedule'!F30) -> 20.923479 | G30: =SUM('Fixed Asset Schedule'!G8,'Fixed Asset Schedule'!G16,'Fixed Asset Schedule'!G23,'Fixed Asset Schedule'!G30) -> 18.298447
A31: EBIT | E31: =E29-E30 -> -30.096216 | F31: =F29-F30 -> 14.487699 | G31: =G29-G30 -> 105.03719
A32: less: interest | E32: 0 | F32: 0 | G32: 0
A33: EBT | E33: =E31-E32 -> -30.096216 | F33: =F31-F32 -> 14.487699 | G33: =G31-G32 -> 105.03719
A34: less: Tax | E34: 0 | F34: =F33*Assumptions!$G$105 -> 3.6465537 | G34: =G33*Assumptions!$G$105 -> 26.437861
A35: EAT | E35: =E33-E34 -> -30.096216 | F35: =F33-F34 -> 10.841145 | G35: =G33-G34 -> 78.59933
A36: Transferred to Reserve
A37: Net Profit Margin | E37: =E35/E8 -> -0.12298713 | F37: =F35/F8 -> 0.023887028 | G37: =G35/G8 -> 0.1187532

Sheet Balance Sheet
A1: All Final Values In: | B1: =Converter!C1 -> Lakhs
E2: 1 | F2: 2 | G2: 3
E3: =EOMONTH(Assumptions!G3,11) -> 44286 | F3: =EOMONTH(E3,12) -> 44651 | G3: =EOMONTH(F3,12) -> 45016
A4: Equity & Liabilities
A6: Share Capital | E6: ='Capital Structure'!E16 -> 225 | F6: =E6 -> 225 | G6: =F6 -> 225
A7: Reserve & Surplus | E7: =D7+'Annual P&L'!E35 -> -30.096216 | F7: =E7+'Annual P&L'!F35 -> -19.255071 | G7: =F7+'Annual P&L'!G35 -> 59.344259
A8: Total Shareholders Funds | E8: =SUM(E6:E7) -> 194.90378 | F8: =SUM(F6:F7) -> 205.74493 | G8: =SUM(G6:G7) -> 284.34426
A10: Current Liabilities
A11: Creditors for expenses | E11: ='Working Capital'!E11 -> 10.120191 | F11: ='Working Capital'!F11 -> 12.90789 | G11: ='Working Capital'!G11 -> 16.246936
A12: Creditors for raw materials | E12: ='Working Capital'!E12 -> 0 | F12: ='Working Capital'!F12 -> 0 | G12: ='Working Capital'!G12 -> 0
A13: =[1]Assumptions!A88 -> Inventory | E13: ='Working Capital'!E13 -> 2.7021509 | F13: ='Working Capital'!F13 -> 4.0194709 | G13: ='Working Capital'!G13 -> 5.5971121
A14: =[1]Assumptions!A89 -> Alcoholic Beverages | E14: ='Working Capital'!E14 -> 1.4979474 | F14: ='Working Capital'!F14 -> 2.1828264 | G14: ='Working Capital'!G14 -> 3.0163068
A15: Food | E15: ='Working Capital'!E15 -> 5.3789068 | F15: ='Working Capital'!F15 -> 7.7848354 | G15: ='Working Capital'!G15 -> 10.735005
A17: Total Current Liabilities | E17: =SUM(E11:E16) -> 19.699196 | F17: =SUM(F11:F16) -> 26.895023 | G17: =SUM(G11:G16) -> 35.595361
A19: Total Liabilities | E19: =E8+E17 -> 214.60298 | F19: =F8+F17 -> 232.63995 | G19: =G8+G17 -> 319.93962
A22: Assets
A23: Fixed Assets
A24: ='[1]Capital Structure'!A6 -> Kitchen Equipments and cutlery | E24: ='Fixed Asset Schedule'!E9 -> 26.634247 | F24: ='Fixed Asset Schedule'!F9 -> 22.63911 | G24: ='Fixed Asset Schedule'!G9 -> 19.243243
A25: ='[1]Capital Structure'!A7 -> Refrigeration Equipments | E25: ='Fixed Asset Schedule'!E17 -> 44.390411 | F25: ='Fixed Asset Schedule'!F17 -> 37.731849 | G25: ='Fixed Asset Schedule'!G17 -> 32.072072
A26: ='[1]Capital Structure'!A8 -> Furniture & Fixtures | E26: ='Fixed Asset Schedule'!E24 -> 47.185479 | F26: ='Fixed Asset Schedule'!F24 -> 42.466932 | G26: ='Fixed Asset Schedule'!G24 -> 38.220238
A27: Restaurant Decor | E27: ='Fixed Asset Schedule'!E31 -> 55.512329 | F27: ='Fixed Asset Schedule'!F31 -> 49.961096 | G27: ='Fixed Asset Schedule'!G31 -> 44.964986
A29: Rent Deposits | E29: ='Capital Structure'!E10 -> 10 | F29: =E29 -> 10 | G29: =F29 -> 10
A31: Current Assets
A32: ='[1]Working Capital'!A6 -> Inventory
A33: ='[1]Working Capital'!A7 -> Alcoholic Beverages | E33: ='Working Capital'!E6 -> 2.7021509 | F33: ='Working Capital'!F6 -> 4.0194709 | G33: ='Working Capital'!G6 -> 5.5971121
